Workbook

Sheet Matrix
D3: RESTAURANT PERFORMANCE FACTOR FY2022-23
D6: DT Restaurants
D8: Metric | G8: Weights | I8: Range | M8: Points | O8: Weighted Points
B9: People
B10: Best People | D10: Restaurant Proficiency | G10: 0.1 | I10: ≥ 85.00% | M10: 100 | O10: =M10*$G$10 -> 10
I11: 80.00% to 84.99% | M11: 66 | O11: =M11*$G$10 -> 6.6
I12: 75.00% to 79.99% | M12: 33 | O12: =M12*$G$10 -> 3.3
I13: ≤ 74.99% | M13: 0 | O13: =M13*$G$10 -> 0
D15: Crew Staffing Tiered by Sales Band | G15: 0.1 | I15: 100 Point Band | M15: 100 | O15: =M15*$G$15 -> 10
I16: 75 Pont Band | M16: 66 | O16: =M16*$G$15 -> 6.6
I17: 50 Point Band | M17: 33 | O17: =M17*$G$15 -> 3.3
I18: 25 Point Band | M18: 0 | O18: =M18*$G$15 -> 0
D20: Safety Audit (6 Monthly) | G20: 0.05 | I20: ≥ 95.00% | M20: 100 | O20: =M20*$G$20 -> 5
I21: 85.00% to 94.99% | M21: 66 | O21: =M21*$G$20 -> 3.3
I22: 75.00% to 84.99% | M22: 33 | O22: =M22*$G$20 -> 1.65
I23: < 75.00% | M23: 0 | O23: =M23*$G$20 -> 0
B25: Guest Obsessed | D25: Market Force Complaints Per 10k | G25: 0.15 | I25: Top 25% of Restaurants | M25: 100 | O25: =M25*$G$25 -> 15
I26: Between 25-50% | M26: 66 | O26: =M26*$G$25 -> 9.9
I27: Between 50-75% | M27: 33 | O27: =M27*$G$25 -> 4.95
I28: Bottom 25% | M28: 0 | O28: =M28*$G$25 -> 0
D30: Perfect Car Count | G30: 0.1 | I30: Top 25% of Restaurants | M30: 100 | O30: =M30*$G$30 -> 10
I31: Between 25-50% | M31: 66 | O31: =M31*$G$30 -> 6.6
I32: Between 50-75% | M32: 33 | O32: =M32*$G$30 -> 3.3
I33: Bottom 25% | M33: 0 | O33: =M33*$G$30 -> 0
D35: REV | G35: Bonus or Penalty | I35: A Grade REV | M35: +25% | O35: 25
I36: 1st Failed REV | M36: -25 | O36: -25
I37: 2nd Failed REV | M37: -100 | O37: -100
B39: Sales | D39: Sales Vs Budget with Bonus | G39: 0.25 | I39: Bonus ≥ 5% Vs Budget | M39: 200 | O39: =M39*$G$39 -> 50
I40: > Budget to 4.99% | M40: 100 | O40: =M40*$G$39 -> 25
I41: = Budget | M41: 90 | O41: =M41*$G$39 -> 22.5
I42: ≤ Budget | M42: 0 | O42: =M42*$G$39 -> 0
B44: Profit | D44: Waste % Vs Budget | G44: 0.1 | I44: < Budget | M44: 100 | O44: =M44*$G$44 -> 10
I45: = Budget | M45: 75 | O45: =M45*$G$44 -> 7.5
I46: > Budget | M46: 0 | O46: =M46*$G$44 -> 0
D48: Total Labour Vs Budget | G48: 0.15 | I48: ≤ Benchmark | M48: 100 | O48: =M48*$G$48 -> 15
I49: ≤ Budget | M49: 90 | O49: =M49*$G$48 -> 13.5
I50: > Budget | M50: 0 | O50: =M50*$G$48 -> 0
D52: EBITDA Vs Budget | G52: Qualifier
B57: Total | D57: 100

Sheet Half 1
G3: RESTAURANT PERFORMANCE FACTOR FY2021-22
D6: Month: | G6: Half 1 | S6: Weeks | T6: 5
D8: Store:
D10: Metric | G10: Weights | I10: Weighted Points | M10: Points | O10: Total
B11: People
B12: Best People | D12: =Matrix!D10 -> Restaurant Proficiency | G12: =Matrix!G10 -> 0.1 | I12: Jul | J12: =IF(ISBLANK(Jul!J13),"",Jul!O13) | M12: =IF(J18<=0,100,IF(J18<5%,75,IF(J18<7.5%,50,IF(J18<10%,25,0)))) -> 100 | O12: =J18 -> 0
I13: Aug | J13: =IF(ISBLANK(Aug!J13),"",Aug!O13)
I14: Sep | J14: =IF(ISBLANK(Sep!J13),"",Sep!O13)
I15: Oct | J15: =IF(ISBLANK(Oct!J13),"",Oct!O13)
I16: Nov | J16: =IF(ISBLANK(Nov!J13),"",Nov!O13)
I17: Dec | J17: =IF(ISBLANK(Dec!J13),"",Dec!O13)
I18: Average | J18: =IFERROR(AVERAGE(J12:K17),0) -> 0
D20: =Matrix!D15 -> Crew Staffing Tiered by Sales Band | G20: =Matrix!G15 -> 0.1 | I20: Jul | J20: =IF(ISBLANK(Jul!K21),"",Jul!O21) | M20: =IFERROR(IF(ISBLANK(K20),0,IF(J26>=T26,100,IF(J26>=T23,75,IF(J26>=T22,50,IF(J26>=T21,25,0))))),0) -> 0 | O20: =J26 -> 0 | S20: Rounded Sales | T20: =FLOOR(U58,5000) -> #REF!
I21: Aug | J21: =IF(ISBLANK(Aug!K21),"",Aug!O21) | S21: Tier 1 | T21: =VLOOKUP($T$20,'Crew Staffing Bands'!$A$1:$E$23,2,FALSE) -> #REF!
I22: Sep | J22: =IF(ISBLANK(Sep!K21),"",Sep!O21) | S22: Tier 2 | T22: =VLOOKUP($T$20,'Crew Staffing Bands'!$A$1:$E$23,3,FALSE) -> #REF!
I23: Oct | J23: =IF(ISBLANK(Oct!K21),"",Oct!O21) | S23: Tier 3 | T23: =VLOOKUP($T$20,'Crew Staffing Bands'!$A$1:$E$23,4,FALSE) -> #REF!
I24: Nov | J24: =IF(ISBLANK(Nov!K21),"",Nov!O21)
I25: Dec | J25: =IF(ISBLANK(Dec!K21),"",Dec!O21)
I26: Average | J26: =IFERROR(AVERAGE(J20:K25),0) -> 0 | S26: Tier 4 | T26: =VLOOKUP($T$20,'Crew Staffing Bands'!$A$1:$E$23,5,FALSE) -> #REF!
D28: =Matrix!D20 -> Safety Audit (6 Monthly) | G28: =Matrix!G20 -> 0.05 | I28: H1 Result | J28: =IF(ISBLANK(Dec!J28),"Complete in December",Dec!J28) -> Complete in December | M28: =IF(J28="Complete in December",0,IF(J28>=0.95,100,IF(J28>=0.8,75,IF(J28>=0.7,50,IF(J28>=0.6,25,0))))) -> 0 | O28: =M28*$G$28 -> 0
B31: Guest Obsessed | D31: =Matrix!D25 -> Market Force Complaints Per 10k | G31: =Matrix!G25 -> 0.15 | I31: Jul | J31: =IF(ISBLANK(Jul!K32),"",Jul!O32) | M31: =IF(J37<2.8,100,IF(J37<3.03,75,IF(J37<3.27,50,IF(J37<=3.5,25,0)))) -> 100 | O31: =J37 -> 0
I32: Aug | J32: =IF(ISBLANK(Aug!K32),"",Aug!O32)
I33: Sep | J33: =IF(ISBLANK(Sep!K32),"",Sep!O32)
I34: Oct | J34: =IF(ISBLANK(Oct!K32),"",Oct!O32)
I35: Nov | J35: =IF(ISBLANK(Nov!K32),"",Nov!O32)
I36: Dec | J36: =IF(ISBLANK(Dec!K32),"",Dec!O32)
I37: Average | J37: =IFERROR(AVERAGE(J31:K36),0) -> 0
D39: =Matrix!D30 -> Perfect Car Count | G39: =Matrix!G30 -> 0.1 | I39: Jul | J39: =IF(ISBLANK(Jul!J40),"",Jul!O40) | M39: =IF(ISBLANK(J39),0,IF(J45<=T39,100,IF(J45<=T40,75,IF(J45<=T41,50,IF(J45<=T42,25,0))))) -> 100 | O39: =J45 -> 0 | S39: Tier 1 | T39: 0.024305556
I40: Aug | J40: =IF(ISBLANK(Aug!J40),"",Aug!O40) | S40: Tier 2 | T40: 0.025694444
I41: Sep | J41: =IF(ISBLANK(Sep!J40),"",Sep!O40) | S41: Tier 3 | T41: 0.026388889
I42: Oct | J42: =IF(ISBLANK(Oct!J40),"",Oct!O40) | S42: Tier 4 | T42: 0.027083333
I43: Nov | J43: =IF(ISBLANK(Nov!J40),"",Nov!O40)
I44: Dec | J44: =IF(ISBLANK(Dec!J40),"",Dec!O40)
I45: Average | J45: =IFERROR(AVERAGE(J39:K44),0) -> 0
D47: =Matrix!D35 -> REV | G47: =Matrix!G35 -> Bonus or Penalty | I47: Grade | J47: =IF(OR(Jul!J47="A",Aug!J47="A",Sep!J47="A",Oct!J47="A",Nov!J47="A",Dec!J47="A"),"A",IF(OR(Jul!J47="2nd Fail",Aug!J47="2nd Fail",Sep!J47="2nd Fail",Oct!J47="2nd Fail",Nov!J47="2nd Fail",Dec!J47="2nd Fail"),"2nd Fail",IF(OR(Jul!J47="1st Fail",Aug!J47="1st Fail",Dec!J47="1st Fail",Sep!J47="1st Fail",Oct!J47="1st Fail",Nov!J47="1st Fail"),"1st Fail","N/A"))) -> N/A | M47: =IF(J47=W47,Matrix!M35,IF(J47=W51,Matrix!M36,IF(J47=W52,Matrix!M37,0))) -> 0 | O47: =IF(M47=Matrix!M35,SUM(O12,O20,O28,O31,O39,O50,O58,O66)*0.25,IF(M47=Matrix!M36,Matrix!M36,IF(M47=Matrix!M37,Matrix!M37,0))) -> 0 | W47: A
W48: B
W49: C
B50: Sales | D50: =Matrix!D39 -> Sales Vs Budget with Bonus | G50: =Matrix!G39 -> 0.25 | I50: Jul | J50: =IF(ISBLANK(Jul!K51),"",Jul!O51) | M50: =IF(J56="",0,IF(J56>=3%,100,IF(J56>=2%,75,IF(J56>=1%,50,IF(J56>=0,25,0))))) -> 25 | O50: =J56 -> 0 | S50: =J50/T6 -> #VALUE! | T50: =K50 -> 0 | U50: =(T50-S50)/S50 -> #VALUE! | W50: 1st Fail
I51: Aug | J51: =IF(ISBLANK(Aug!K51),"",Aug!O51) | S51: =S50*2 -> #VALUE! | T51: =SUM(K50:K51) -> 0 | U51: =(T51-S51)/S51 -> #VALUE! | W51: 2nd Fail
I52: Sep | J52: =IF(ISBLANK(Sep!K51),"",Sep!O51) | S52: =S50*3 -> #VALUE! | T52: =SUM(K50:K52) -> 0 | U52: =(T52-S52)/S52 -> #VALUE!
...

Sheet Benchmarks
B2: Market Force | D2: PCC | F2: JEDI | H2: Safety Audit | J2: Sales
B3: High | C3: Low | D3: High | E3: Low | F3: High | G3: Low | H3: High | I3: Low | J3: High | K3: Low
A4: 1 | B4: 3.58 | C4: 0 | E4: 55 | F4: 1 | G4: 0.85 | H4: 1 | I4: 0.95 | K4: 0.05
A5: 2 | B5: 5.25 | C5: 3.59 | D5: 54 | E5: 49 | F5: 0.8499 | G5: 0.8 | H5: 0.9499 | I5: 0.85 | J5: 0.0499 | K5: 0
A6: 3 | B6: 7.44 | C6: 5.26 | D6: 48 | E6: 41 | F6: 0.7999 | G6: 0.75 | H6: 0.8499 | I6: 0.75 | J6: 0 | K6: 0
A7: 4 | C7: 7.45 | D7: 40 | F7: 0.7499 | G7: 0 | H7: 0.75 | I7: 0 | K7: -0.0001

Sheet Jul
D3: RESTAURANT PERFORMANCE FACTOR FY2022-23
D6: Month: | G6: July | S6: Weeks | T6: 4
D8: Store: | M8: State:
D10: Metric | G10: Weights | I10: Result | M10: Points | O10: Weighted Points
B11: People
J12: Proficiency %
B13: Best People | D13: =Matrix!D10 -> Restaurant Proficiency | G13: =Matrix!G10 -> 0.1 | I13: Week 1 | M13: =IF(J18="",0,IF(J18>=Benchmarks!G4,Matrix!M10,IF(J18>=Benchmarks!G5,Matrix!M11,IF(J18>=Benchmarks!G6,Matrix!M12,Matrix!M13)))) -> 0 | O13: =M13*$G$13 -> 0
I14: Week 2
I15: Week 3
I16: Week 4
I17: Week 5
I18: Total | J18: {=IF(ISBLANK(J13),"",(LOOKUP(2,1/(J13:J17<>""),J13:J17)))}
J20: Target | K20: Actual
D21: =Matrix!D15 -> Crew Staffing Tiered by Sales Band | G21: =Matrix!G15 -> 0.1 | I21: Week 1 | J21: =IFERROR(T26,"Enter Sales") -> Enter Sales | M21: =IFERROR(IF(ISBLANK(K21),0,IF(J26>=T26,Matrix!M15,IF(J26>=T24,Matrix!M16,IF(J26>=T23,Matrix!M17,Matrix!M18)))),0) -> 0 | O21: =M21*$G$21 -> 0 | S21: Rounded Sales | T21: =MROUND(U59,5000) -> 0
I22: Week 2 | S22: Tier 1 | T22: =VLOOKUP($T$21,'Crew Staffing Bands'!$A$1:$E$23,2,FALSE) -> #N/A
I23: Week 3 | S23: Tier 2 | T23: =VLOOKUP($T$21,'Crew Staffing Bands'!$A$1:$E$23,3,FALSE) -> #N/A
I24: Week 4 | S24: Tier 3 | T24: =VLOOKUP($T$21,'Crew Staffing Bands'!$A$1:$E$23,4,FALSE) -> #N/A
I25: Week 5
I26: Total | J26: {=IF(ISBLANK(K21),"",(LOOKUP(2,1/(K21:K25<>""),K21:K25)))} | S26: Tier 4 | T26: =VLOOKUP($T$21,'Crew Staffing Bands'!$A$1:$E$23,5,FALSE) -> #N/A
D28: =Matrix!D20 -> Safety Audit (6 Monthly) | G28: =Matrix!G20 -> 0.05 | I28: H1 Result | J28: =IF(ISBLANK(Dec!J28),"Complete in December",Dec!J28) -> Complete in December | M28: =IF(J28="Complete in December",0,IF(J28>=Benchmarks!I4,Matrix!M20,IF(J28>=Benchmarks!I5,Matrix!M21,IF(J28>=Benchmarks!I6,Matrix!M22,Matrix!M23)))) -> 0 | O28: =M28*$G$28 -> 0
J31: Customers | K31: Complaints
B32: Guest Obsessed | D32: =Matrix!D25 -> Market Force Complaints Per 10k | G32: =Matrix!G25 -> 0.15 | I32: Week 1 | M32: =IF(J37<=Benchmarks!C5,Matrix!M25,IF(J37<Benchmarks!C6,Matrix!M26,IF(J37<Benchmarks!C7,Matrix!M27,Matrix!M28))) -> 0 | O32: =M32*$G$32 -> 0
I33: Week 2
I34: Week 3
I35: Week 4
I36: Week 5
I37: Total | J37: =IF(ISBLANK(K32),"",SUM(K31:K36)/(SUM(J31:J36)/10000))
J39: Slow Point | K39: PCC
D40: =Matrix!D30 -> Perfect Car Count | G40: =Matrix!G30 -> 0.1 | I40: Week 1 | K40: =IF(ISBLANK(J40),"",_xlfn.FLOOR.MATH(3600/(J40*(24*60)))) | M40: =IF(ISBLANK(J40),0,IF(J45>=Benchmarks!E4,Matrix!M30,IF(J45>=Benchmarks!E5,Matrix!M31,IF(J45>=Benchmarks!E6,Matrix!M32,Matrix!M33)))) -> 0 | O40: =M40*$G$40 -> 0 | S40: Tier 1 | T40: 0.024305556
I41: Week 2 | K41: =IF(ISBLANK(J41),"",_xlfn.FLOOR.MATH(3600/(J41*(24*60)))) | S41: Tier 2 | T41: 0.025694444
I42: Week 3 | K42: =IF(ISBLANK(J42),"",_xlfn.FLOOR.MATH(3600/(J42*(24*60)))) | S42: Tier 3 | T42: 0.026388889
I43: Week 4 | K43: =IF(ISBLANK(J43),"",_xlfn.FLOOR.MATH(3600/(J43*(24*60)))) | S43: Tier 4 | T43: 0.027083333
I44: Week 5 | K44: =IF(ISBLANK(J44),"",_xlfn.FLOOR.MATH(3600/(J44*(24*60))))
I45: Total | J45: =IF(ISBLANK(J40),"",3600/(AVERAGE(J40:J44)*(24*60)))
D47: =Matrix!D35 -> REV | G47: =Matrix!G35 -> Bonus or Penalty | I47: Grade | M47: =IF(J47=W47,Matrix!M35,IF(J47=W51,Matrix!M36,IF(J47=W52,Matrix!M37,0))) -> 0 | O47: =IF(M47=Matrix!M35,SUM(O13,O21,O28,O32,O40,O51,O59,O67)*0.25,IF(M47=Matrix!M36,Matrix!M36,IF(M47=Matrix!M37,Matrix!M37,0))) -> 0 | W47: A
W48: B
W49: C
J50: Budget | K50: T/Y | W50: D
B51: Sales | D51: =Matrix!D39 -> Sales Vs Budget with Bonus | G51: =Matrix!G39 -> 0.25 | I51: Week 1 | M51: =IF(J56="",0,IF(J56>=Benchmarks!K4,Matrix!M39,IF(J56>Benchmarks!K5,Matrix!M40,IF(J56=Benchmarks!K6,Matrix!M41,Matrix!M42)))) -> 0 | O51: =M51*$G$51 -> 0 | S51: =J51/T6 -> 0 | T51: =K51 -> 0 | U51: =(T51-S51)/S51 -> #DIV/0! | W51: 1st Fail
I52: Week 2 | S52: =S51*2 -> 0 | T52: =SUM(K51:K52) -> 0 | U52: =(T52-S52)/S52 -> #DIV/0! | W52: 2nd Fail
...

Sheet Aug
D3: RESTAURANT PERFORMANCE FACTOR FY2022-23
D6: Month: | G6: August | S6: Weeks | T6: 4
D8: Store: | M8: State:
D10: Metric | G10: Weights | I10: Result | M10: Points | O10: Weighted Points
B11: People
J12: Proficiency %
B13: Best People | D13: =Matrix!D10 -> Restaurant Proficiency | G13: =Matrix!G10 -> 0.1 | I13: Week 1 | M13: =IF(J18="",0,IF(J18>=Benchmarks!G4,Matrix!M10,IF(J18>=Benchmarks!G5,Matrix!M11,IF(J18>=Benchmarks!G6,Matrix!M12,Matrix!M13)))) -> 0 | O13: =M13*$G$13 -> 0
I14: Week 2
I15: Week 3
I16: Week 4
I17: Week 5
I18: Total | J18: {=IF(ISBLANK(J13),"",(LOOKUP(2,1/(J13:J17<>""),J13:J17)))}
J20: Target | K20: Actual
D21: =Matrix!D15 -> Crew Staffing Tiered by Sales Band | G21: =Matrix!G15 -> 0.1 | I21: Week 1 | J21: =IFERROR(T26,"Enter Sales") -> Enter Sales | M21: =IFERROR(IF(ISBLANK(K21),0,IF(J26>=T26,Matrix!M15,IF(J26>=T24,Matrix!M16,IF(J26>=T23,Matrix!M17,Matrix!M18)))),0) -> 0 | O21: =M21*$G$21 -> 0 | S21: Rounded Sales | T21: =MROUND(U59,5000) -> 0
I22: Week 2 | S22: Tier 1 | T22: =VLOOKUP($T$21,'Crew Staffing Bands'!$A$1:$E$23,2,FALSE) -> #N/A
I23: Week 3 | S23: Tier 2 | T23: =VLOOKUP($T$21,'Crew Staffing Bands'!$A$1:$E$23,3,FALSE) -> #N/A
I24: Week 4 | S24: Tier 3 | T24: =VLOOKUP($T$21,'Crew Staffing Bands'!$A$1:$E$23,4,FALSE) -> #N/A
I25: Week 5
I26: Total | J26: {=IF(ISBLANK(K21),"",(LOOKUP(2,1/(K21:K25<>""),K21:K25)))} | S26: Tier 4 | T26: =VLOOKUP($T$21,'Crew Staffing Bands'!$A$1:$E$23,5,FALSE) -> #N/A
D28: =Matrix!D20 -> Safety Audit (6 Monthly) | G28: =Matrix!G20 -> 0.05 | I28: H1 Result | J28: =IF(ISBLANK(Dec!J28),"Complete in December",Dec!J28) -> Complete in December | M28: =IF(J28="Complete in December",0,IF(J28>=Benchmarks!I4,Matrix!M20,IF(J28>=Benchmarks!I5,Matrix!M21,IF(J28>=Benchmarks!I6,Matrix!M22,Matrix!M23)))) -> 0 | O28: =M28*$G$28 -> 0
J31: Customers | K31: Complaints
B32: Guest Obsessed | D32: =Matrix!D25 -> Market Force Complaints Per 10k | G32: =Matrix!G25 -> 0.15 | I32: Week 1 | M32: =IF(J37<=Benchmarks!C5,Matrix!M25,IF(J37<Benchmarks!C6,Matrix!M26,IF(J37<Benchmarks!C7,Matrix!M27,Matrix!M28))) -> 0 | O32: =M32*$G$32 -> 0
I33: Week 2
I34: Week 3
I35: Week 4
I36: Week 5
I37: Total | J37: =IF(ISBLANK(K32),"",SUM(K31:K36)/(SUM(J31:J36)/10000))
J39: Slow Point | K39: PCC
D40: =Matrix!D30 -> Perfect Car Count | G40: =Matrix!G30 -> 0.1 | I40: Week 1 | K40: =IF(ISBLANK(J40),"",_xlfn.FLOOR.MATH(3600/(J40*(24*60)))) | M40: =IF(ISBLANK(J40),0,IF(J45>=Benchmarks!E4,Matrix!M30,IF(J45>=Benchmarks!E5,Matrix!M31,IF(J45>=Benchmarks!E6,Matrix!M32,Matrix!M33)))) -> 0 | O40: =M40*$G$40 -> 0 | S40: Tier 1 | T40: 0.024305556
I41: Week 2 | K41: =IF(ISBLANK(J41),"",_xlfn.FLOOR.MATH(3600/(J41*(24*60)))) | S41: Tier 2 | T41: 0.025694444
I42: Week 3 | K42: =IF(ISBLANK(J42),"",_xlfn.FLOOR.MATH(3600/(J42*(24*60)))) | S42: Tier 3 | T42: 0.026388889
I43: Week 4 | K43: =IF(ISBLANK(J43),"",_xlfn.FLOOR.MATH(3600/(J43*(24*60)))) | S43: Tier 4 | T43: 0.027083333
I44: Week 5 | K44: =IF(ISBLANK(J44),"",_xlfn.FLOOR.MATH(3600/(J44*(24*60))))
I45: Total | J45: =IF(ISBLANK(J40),"",3600/(AVERAGE(J40:J44)*(24*60)))
D47: =Matrix!D35 -> REV | G47: =Matrix!G35 -> Bonus or Penalty | I47: Grade | M47: =IF(J47=W47,Matrix!M35,IF(J47=W51,Matrix!M36,IF(J47=W52,Matrix!M37,0))) -> 0 | O47: =IF(M47=Matrix!M35,SUM(O13,O21,O28,O32,O40,O51,O59,O67)*0.25,IF(M47=Matrix!M36,Matrix!M36,IF(M47=Matrix!M37,Matrix!M37,0))) -> 0 | W47: A
W48: B
W49: C
J50: Budget | K50: T/Y | W50: D
B51: Sales | D51: =Matrix!D39 -> Sales Vs Budget with Bonus | G51: =Matrix!G39 -> 0.25 | I51: Week 1 | M51: =IF(J56="",0,IF(J56>=Benchmarks!K4,Matrix!M39,IF(J56>Benchmarks!K5,Matrix!M40,IF(J56=Benchmarks!K6,Matrix!M41,Matrix!M42)))) -> 0 | O51: =M51*$G$51 -> 0 | S51: =J51/T6 -> 0 | T51: =K51 -> 0 | U51: =(T51-S51)/S51 -> #DIV/0! | W51: 1st Fail
I52: Week 2 | S52: =S51*2 -> 0 | T52: =SUM(K51:K52) -> 0 | U52: =(T52-S52)/S52 -> #DIV/0! | W52: 2nd Fail
...

Sheet Sep
D3: RESTAURANT PERFORMANCE FACTOR FY2022-23
D6: Month: | G6: September | S6: Weeks | T6: 5
D8: Store: | M8: State:
D10: Metric | G10: Weights | I10: Result | M10: Points | O10: Weighted Points
B11: People
J12: Proficiency %
B13: Best People | D13: =Matrix!D10 -> Restaurant Proficiency | G13: =Matrix!G10 -> 0.1 | I13: Week 1 | M13: =IF(J18="",0,IF(J18>=Benchmarks!G4,Matrix!M10,IF(J18>=Benchmarks!G5,Matrix!M11,IF(J18>=Benchmarks!G6,Matrix!M12,Matrix!M13)))) -> 0 | O13: =M13*$G$13 -> 0
I14: Week 2
I15: Week 3
I16: Week 4
I17: Week 5
I18: Total | J18: {=IF(ISBLANK(J13),"",(LOOKUP(2,1/(J13:J17<>""),J13:J17)))}
J20: Target | K20: Actual
D21: =Matrix!D15 -> Crew Staffing Tiered by Sales Band | G21: =Matrix!G15 -> 0.1 | I21: Week 1 | J21: =IFERROR(T26,"Enter Sales") -> Enter Sales | M21: =IFERROR(IF(ISBLANK(K21),0,IF(J26>=T26,Matrix!M15,IF(J26>=T24,Matrix!M16,IF(J26>=T23,Matrix!M17,Matrix!M18)))),0) -> 0 | O21: =M21*$G$21 -> 0 | S21: Rounded Sales | T21: =MROUND(U59,5000) -> 0
I22: Week 2 | S22: Tier 1 | T22: =VLOOKUP($T$21,'Crew Staffing Bands'!$A$1:$E$23,2,FALSE) -> #N/A
I23: Week 3 | S23: Tier 2 | T23: =VLOOKUP($T$21,'Crew Staffing Bands'!$A$1:$E$23,3,FALSE) -> #N/A
I24: Week 4 | S24: Tier 3 | T24: =VLOOKUP($T$21,'Crew Staffing Bands'!$A$1:$E$23,4,FALSE) -> #N/A
I25: Week 5
I26: Total | J26: {=IF(ISBLANK(K21),"",(LOOKUP(2,1/(K21:K25<>""),K21:K25)))} | S26: Tier 4 | T26: =VLOOKUP($T$21,'Crew Staffing Bands'!$A$1:$E$23,5,FALSE) -> #N/A
D28: =Matrix!D20 -> Safety Audit (6 Monthly) | G28: =Matrix!G20 -> 0.05 | I28: H1 Result | J28: =IF(ISBLANK(Dec!J28),"Complete in December",Dec!J28) -> Complete in December | M28: =IF(J28="Complete in December",0,IF(J28>=Benchmarks!I4,Matrix!M20,IF(J28>=Benchmarks!I5,Matrix!M21,IF(J28>=Benchmarks!I6,Matrix!M22,Matrix!M23)))) -> 0 | O28: =M28*$G$28 -> 0
J31: Customers | K31: Complaints
B32: Guest Obsessed | D32: =Matrix!D25 -> Market Force Complaints Per 10k | G32: =Matrix!G25 -> 0.15 | I32: Week 1 | M32: =IF(J37<=Benchmarks!C5,Matrix!M25,IF(J37<Benchmarks!C6,Matrix!M26,IF(J37<Benchmarks!C7,Matrix!M27,Matrix!M28))) -> 0 | O32: =M32*$G$32 -> 0
I33: Week 2
I34: Week 3
I35: Week 4
I36: Week 5
I37: Total | J37: =IF(ISBLANK(K32),"",SUM(K31:K36)/(SUM(J31:J36)/10000))
J39: Slow Point | K39: PCC
D40: =Matrix!D30 -> Perfect Car Count | G40: =Matrix!G30 -> 0.1 | I40: Week 1 | K40: =IF(ISBLANK(J40),"",_xlfn.FLOOR.MATH(3600/(J40*(24*60)))) | M40: =IF(ISBLANK(J40),0,IF(J45>=Benchmarks!E4,Matrix!M30,IF(J45>=Benchmarks!E5,Matrix!M31,IF(J45>=Benchmarks!E6,Matrix!M32,Matrix!M33)))) -> 0 | O40: =M40*$G$40 -> 0 | S40: Tier 1 | T40: 0.024305556
I41: Week 2 | K41: =IF(ISBLANK(J41),"",_xlfn.FLOOR.MATH(3600/(J41*(24*60)))) | S41: Tier 2 | T41: 0.025694444
I42: Week 3 | K42: =IF(ISBLANK(J42),"",_xlfn.FLOOR.MATH(3600/(J42*(24*60)))) | S42: Tier 3 | T42: 0.026388889
I43: Week 4 | K43: =IF(ISBLANK(J43),"",_xlfn.FLOOR.MATH(3600/(J43*(24*60)))) | S43: Tier 4 | T43: 0.027083333
I44: Week 5 | K44: =IF(ISBLANK(J44),"",_xlfn.FLOOR.MATH(3600/(J44*(24*60))))
I45: Total | J45: =IF(ISBLANK(J40),"",3600/(AVERAGE(J40:J44)*(24*60)))
D47: =Matrix!D35 -> REV | G47: =Matrix!G35 -> Bonus or Penalty | I47: Grade | M47: =IF(J47=W47,Matrix!M35,IF(J47=W51,Matrix!M36,IF(J47=W52,Matrix!M37,0))) -> 0 | O47: =IF(M47=Matrix!M35,SUM(O13,O21,O28,O32,O40,O51,O59,O67)*0.25,IF(M47=Matrix!M36,Matrix!M36,IF(M47=Matrix!M37,Matrix!M37,0))) -> 0 | W47: A
W48: B
W49: C
J50: Budget | K50: T/Y | W50: D
B51: Sales | D51: =Matrix!D39 -> Sales Vs Budget with Bonus | G51: =Matrix!G39 -> 0.25 | I51: Week 1 | M51: =IF(J56="",0,IF(J56>=Benchmarks!K4,Matrix!M39,IF(J56>Benchmarks!K5,Matrix!M40,IF(J56=Benchmarks!K6,Matrix!M41,Matrix!M42)))) -> 0 | O51: =M51*$G$51 -> 0 | S51: =J51/T6 -> 0 | T51: =K51 -> 0 | U51: =(T51-S51)/S51 -> #DIV/0! | W51: 1st Fail
I52: Week 2 | S52: =S51*2 -> 0 | T52: =SUM(K51:K52) -> 0 | U52: =(T52-S52)/S52 -> #DIV/0! | W52: 2nd Fail
...

Sheet Oct
D3: RESTAURANT PERFORMANCE FACTOR FY2022-23
D6: Month: | G6: October | S6: Weeks | T6: 4
D8: Store: | M8: State:
D10: Metric | G10: Weights | I10: Result | M10: Points | O10: Weighted Points
B11: People
J12: Proficiency %
B13: Best People | D13: =Matrix!D10 -> Restaurant Proficiency | G13: =Matrix!G10 -> 0.1 | I13: Week 1 | M13: =IF(J18="",0,IF(J18>=Benchmarks!G4,Matrix!M10,IF(J18>=Benchmarks!G5,Matrix!M11,IF(J18>=Benchmarks!G6,Matrix!M12,Matrix!M13)))) -> 0 | O13: =M13*$G$13 -> 0
I14: Week 2
I15: Week 3
I16: Week 4
I17: Week 5
I18: Total | J18: {=IF(ISBLANK(J13),"",(LOOKUP(2,1/(J13:J17<>""),J13:J17)))}
J20: Target | K20: Actual
D21: =Matrix!D15 -> Crew Staffing Tiered by Sales Band | G21: =Matrix!G15 -> 0.1 | I21: Week 1 | J21: =IFERROR(T26,"Enter Sales") -> Enter Sales | M21: =IFERROR(IF(ISBLANK(K21),0,IF(J26>=T26,Matrix!M15,IF(J26>=T24,Matrix!M16,IF(J26>=T23,Matrix!M17,Matrix!M18)))),0) -> 0 | O21: =M21*$G$21 -> 0 | S21: Rounded Sales | T21: =MROUND(U59,5000) -> 0
I22: Week 2 | S22: Tier 1 | T22: =VLOOKUP($T$21,'Crew Staffing Bands'!$A$1:$E$23,2,FALSE) -> #N/A
I23: Week 3 | S23: Tier 2 | T23: =VLOOKUP($T$21,'Crew Staffing Bands'!$A$1:$E$23,3,FALSE) -> #N/A
I24: Week 4 | S24: Tier 3 | T24: =VLOOKUP($T$21,'Crew Staffing Bands'!$A$1:$E$23,4,FALSE) -> #N/A
I25: Week 5
I26: Total | J26: {=IF(ISBLANK(K21),"",(LOOKUP(2,1/(K21:K25<>""),K21:K25)))} | S26: Tier 4 | T26: =VLOOKUP($T$21,'Crew Staffing Bands'!$A$1:$E$23,5,FALSE) -> #N/A
D28: =Matrix!D20 -> Safety Audit (6 Monthly) | G28: =Matrix!G20 -> 0.05 | I28: H1 Result | J28: =IF(ISBLANK(Dec!J28),"Complete in December",Dec!J28) -> Complete in December | M28: =IF(J28="Complete in December",0,IF(J28>=Benchmarks!I4,Matrix!M20,IF(J28>=Benchmarks!I5,Matrix!M21,IF(J28>=Benchmarks!I6,Matrix!M22,Matrix!M23)))) -> 0 | O28: =M28*$G$28 -> 0
J31: Customers | K31: Complaints
B32: Guest Obsessed | D32: =Matrix!D25 -> Market Force Complaints Per 10k | G32: =Matrix!G25 -> 0.15 | I32: Week 1 | M32: =IF(J37<=Benchmarks!C5,Matrix!M25,IF(J37<Benchmarks!C6,Matrix!M26,IF(J37<Benchmarks!C7,Matrix!M27,Matrix!M28))) -> 0 | O32: =M32*$G$32 -> 0
I33: Week 2
I34: Week 3
I35: Week 4
I36: Week 5
I37: Total | J37: =IF(ISBLANK(K32),"",SUM(K31:K36)/(SUM(J31:J36)/10000))
J39: Slow Point | K39: PCC
D40: =Matrix!D30 -> Perfect Car Count | G40: =Matrix!G30 -> 0.1 | I40: Week 1 | K40: =IF(ISBLANK(J40),"",_xlfn.FLOOR.MATH(3600/(J40*(24*60)))) | M40: =IF(ISBLANK(J40),0,IF(J45>=Benchmarks!E4,Matrix!M30,IF(J45>=Benchmarks!E5,Matrix!M31,IF(J45>=Benchmarks!E6,Matrix!M32,Matrix!M33)))) -> 0 | O40: =M40*$G$40 -> 0 | S40: Tier 1 | T40: 0.024305556
I41: Week 2 | K41: =IF(ISBLANK(J41),"",_xlfn.FLOOR.MATH(3600/(J41*(24*60)))) | S41: Tier 2 | T41: 0.025694444
I42: Week 3 | K42: =IF(ISBLANK(J42),"",_xlfn.FLOOR.MATH(3600/(J42*(24*60)))) | S42: Tier 3 | T42: 0.026388889
I43: Week 4 | K43: =IF(ISBLANK(J43),"",_xlfn.FLOOR.MATH(3600/(J43*(24*60)))) | S43: Tier 4 | T43: 0.027083333
I44: Week 5 | K44: =IF(ISBLANK(J44),"",_xlfn.FLOOR.MATH(3600/(J44*(24*60))))
I45: Total | J45: =IF(ISBLANK(J40),"",3600/(AVERAGE(J40:J44)*(24*60)))
D47: =Matrix!D35 -> REV | G47: =Matrix!G35 -> Bonus or Penalty | I47: Grade | M47: =IF(J47=W47,Matrix!M35,IF(J47=W51,Matrix!M36,IF(J47=W52,Matrix!M37,0))) -> 0 | O47: =IF(M47=Matrix!M35,SUM(O13,O21,O28,O32,O40,O51,O59,O67)*0.25,IF(M47=Matrix!M36,Matrix!M36,IF(M47=Matrix!M37,Matrix!M37,0))) -> 0 | W47: A
W48: B
W49: C
J50: Budget | K50: T/Y | W50: D
B51: Sales | D51: =Matrix!D39 -> Sales Vs Budget with Bonus | G51: =Matrix!G39 -> 0.25 | I51: Week 1 | M51: =IF(J56="",0,IF(J56>=Benchmarks!K4,Matrix!M39,IF(J56>Benchmarks!K5,Matrix!M40,IF(J56=Benchmarks!K6,Matrix!M41,Matrix!M42)))) -> 0 | O51: =M51*$G$51 -> 0 | S51: =J51/T6 -> 0 | T51: =K51 -> 0 | U51: =(T51-S51)/S51 -> #DIV/0! | W51: 1st Fail
I52: Week 2 | S52: =S51*2 -> 0 | T52: =SUM(K51:K52) -> 0 | U52: =(T52-S52)/S52 -> #DIV/0! | W52: 2nd Fail
...

Sheet Nov
D3: RESTAURANT PERFORMANCE FACTOR FY2022-23
D6: Month: | G6: November | S6: Weeks | T6: 4
D8: Store: | M8: State:
D10: Metric | G10: Weights | I10: Result | M10: Points | O10: Weighted Points
B11: People
J12: Proficiency %
B13: Best People | D13: =Matrix!D10 -> Restaurant Proficiency | G13: =Matrix!G10 -> 0.1 | I13: Week 1 | M13: =IF(J18="",0,IF(J18>=Benchmarks!G4,Matrix!M10,IF(J18>=Benchmarks!G5,Matrix!M11,IF(J18>=Benchmarks!G6,Matrix!M12,Matrix!M13)))) -> 0 | O13: =M13*$G$13 -> 0
I14: Week 2
I15: Week 3
I16: Week 4
I17: Week 5
I18: Total | J18: {=IF(ISBLANK(J13),"",(LOOKUP(2,1/(J13:J17<>""),J13:J17)))}
J20: Target | K20: Actual
D21: =Matrix!D15 -> Crew Staffing Tiered by Sales Band | G21: =Matrix!G15 -> 0.1 | I21: Week 1 | J21: =IFERROR(T26,"Enter Sales") -> Enter Sales | M21: =IFERROR(IF(ISBLANK(K21),0,IF(J26>=T26,Matrix!M15,IF(J26>=T24,Matrix!M16,IF(J26>=T23,Matrix!M17,Matrix!M18)))),0) -> 0 | O21: =M21*$G$21 -> 0 | S21: Rounded Sales | T21: =MROUND(U59,5000) -> 0
I22: Week 2 | S22: Tier 1 | T22: =VLOOKUP($T$21,'Crew Staffing Bands'!$A$1:$E$23,2,FALSE) -> #N/A
I23: Week 3 | S23: Tier 2 | T23: =VLOOKUP($T$21,'Crew Staffing Bands'!$A$1:$E$23,3,FALSE) -> #N/A
I24: Week 4 | S24: Tier 3 | T24: =VLOOKUP($T$21,'Crew Staffing Bands'!$A$1:$E$23,4,FALSE) -> #N/A
I25: Week 5
I26: Total | J26: {=IF(ISBLANK(K21),"",(LOOKUP(2,1/(K21:K25<>""),K21:K25)))} | S26: Tier 4 | T26: =VLOOKUP($T$21,'Crew Staffing Bands'!$A$1:$E$23,5,FALSE) -> #N/A
D28: =Matrix!D20 -> Safety Audit (6 Monthly) | G28: =Matrix!G20 -> 0.05 | I28: H1 Result | J28: =IF(ISBLANK(Dec!J28),"Complete in December",Dec!J28) -> Complete in December | M28: =IF(J28="Complete in December",0,IF(J28>=Benchmarks!I4,Matrix!M20,IF(J28>=Benchmarks!I5,Matrix!M21,IF(J28>=Benchmarks!I6,Matrix!M22,Matrix!M23)))) -> 0 | O28: =M28*$G$28 -> 0
J31: Customers | K31: Complaints
B32: Guest Obsessed | D32: =Matrix!D25 -> Market Force Complaints Per 10k | G32: =Matrix!G25 -> 0.15 | I32: Week 1 | M32: =IF(J37<=Benchmarks!C5,Matrix!M25,IF(J37<Benchmarks!C6,Matrix!M26,IF(J37<Benchmarks!C7,Matrix!M27,Matrix!M28))) -> 0 | O32: =M32*$G$32 -> 0
I33: Week 2
I34: Week 3
I35: Week 4
I36: Week 5
I37: Total | J37: =IF(ISBLANK(K32),"",SUM(K31:K36)/(SUM(J31:J36)/10000))
J39: Slow Point | K39: PCC
D40: =Matrix!D30 -> Perfect Car Count | G40: =Matrix!G30 -> 0.1 | I40: Week 1 | K40: =IF(ISBLANK(J40),"",_xlfn.FLOOR.MATH(3600/(J40*(24*60)))) | M40: =IF(ISBLANK(J40),0,IF(J45>=Benchmarks!E4,Matrix!M30,IF(J45>=Benchmarks!E5,Matrix!M31,IF(J45>=Benchmarks!E6,Matrix!M32,Matrix!M33)))) -> 0 | O40: =M40*$G$40 -> 0 | S40: Tier 1 | T40: 0.024305556
I41: Week 2 | K41: =IF(ISBLANK(J41),"",_xlfn.FLOOR.MATH(3600/(J41*(24*60)))) | S41: Tier 2 | T41: 0.025694444
I42: Week 3 | K42: =IF(ISBLANK(J42),"",_xlfn.FLOOR.MATH(3600/(J42*(24*60)))) | S42: Tier 3 | T42: 0.026388889
I43: Week 4 | K43: =IF(ISBLANK(J43),"",_xlfn.FLOOR.MATH(3600/(J43*(24*60)))) | S43: Tier 4 | T43: 0.027083333
I44: Week 5 | K44: =IF(ISBLANK(J44),"",_xlfn.FLOOR.MATH(3600/(J44*(24*60))))
I45: Total | J45: =IF(ISBLANK(J40),"",3600/(AVERAGE(J40:J44)*(24*60)))
D47: =Matrix!D35 -> REV | G47: =Matrix!G35 -> Bonus or Penalty | I47: Grade | M47: =IF(J47=W47,Matrix!M35,IF(J47=W51,Matrix!M36,IF(J47=W52,Matrix!M37,0))) -> 0 | O47: =IF(M47=Matrix!M35,SUM(O13,O21,O28,O32,O40,O51,O59,O67)*0.25,IF(M47=Matrix!M36,Matrix!M36,IF(M47=Matrix!M37,Matrix!M37,0))) -> 0 | W47: A
W48: B
W49: C
J50: Budget | K50: T/Y | W50: D
B51: Sales | D51: =Matrix!D39 -> Sales Vs Budget with Bonus | G51: =Matrix!G39 -> 0.25 | I51: Week 1 | M51: =IF(J56="",0,IF(J56>=Benchmarks!K4,Matrix!M39,IF(J56>Benchmarks!K5,Matrix!M40,IF(J56=Benchmarks!K6,Matrix!M41,Matrix!M42)))) -> 0 | O51: =M51*$G$51 -> 0 | S51: =J51/T6 -> 0 | T51: =K51 -> 0 | U51: =(T51-S51)/S51 -> #DIV/0! | W51: 1st Fail
I52: Week 2 | S52: =S51*2 -> 0 | T52: =SUM(K51:K52) -> 0 | U52: =(T52-S52)/S52 -> #DIV/0! | W52: 2nd Fail
...

Sheet Dec
D3: RESTAURANT PERFORMANCE FACTOR FY2022-23
D6: Month: | G6: December | S6: Weeks | T6: 5
D8: Store: | M8: State:
D10: Metric | G10: Weights | I10: Result | M10: Points | O10: Weighted Points
B11: People
J12: Proficiency %
B13: Best People | D13: =Matrix!D10 -> Restaurant Proficiency | G13: =Matrix!G10 -> 0.1 | I13: Week 1 | M13: =IF(J18="",0,IF(J18>=Benchmarks!G4,Matrix!M10,IF(J18>=Benchmarks!G5,Matrix!M11,IF(J18>=Benchmarks!G6,Matrix!M12,Matrix!M13)))) -> 0 | O13: =M13*$G$13 -> 0
I14: Week 2
I15: Week 3
I16: Week 4
I17: Week 5
I18: Total | J18: {=IF(ISBLANK(J13),"",(LOOKUP(2,1/(J13:J17<>""),J13:J17)))}
J20: Target | K20: Actual
D21: =Matrix!D15 -> Crew Staffing Tiered by Sales Band | G21: =Matrix!G15 -> 0.1 | I21: Week 1 | J21: =IFERROR(T26,"Enter Sales") -> Enter Sales | M21: =IFERROR(IF(ISBLANK(K21),0,IF(J26>=T26,Matrix!M15,IF(J26>=T24,Matrix!M16,IF(J26>=T23,Matrix!M17,Matrix!M18)))),0) -> 0 | O21: =M21*$G$21 -> 0 | S21: Rounded Sales | T21: =MROUND(U59,5000) -> 0
I22: Week 2 | S22: Tier 1 | T22: =VLOOKUP($T$21,'Crew Staffing Bands'!$A$1:$E$23,2,FALSE) -> #N/A
I23: Week 3 | S23: Tier 2 | T23: =VLOOKUP($T$21,'Crew Staffing Bands'!$A$1:$E$23,3,FALSE) -> #N/A
I24: Week 4 | S24: Tier 3 | T24: =VLOOKUP($T$21,'Crew Staffing Bands'!$A$1:$E$23,4,FALSE) -> #N/A
I25: Week 5
I26: Total | J26: {=IF(ISBLANK(K21),"",(LOOKUP(2,1/(K21:K25<>""),K21:K25)))} | S26: Tier 4 | T26: =VLOOKUP($T$21,'Crew Staffing Bands'!$A$1:$E$23,5,FALSE) -> #N/A
D28: =Matrix!D20 -> Safety Audit (6 Monthly) | G28: =Matrix!G20 -> 0.05 | I28: H1 Result | M28: =IF(J28="Complete in December",0,IF(J28>=Benchmarks!I4,Matrix!M20,IF(J28>=Benchmarks!I5,Matrix!M21,IF(J28>=Benchmarks!I6,Matrix!M22,Matrix!M23)))) -> 0 | O28: =M28*$G$28 -> 0
J31: Customers | K31: Complaints
B32: Guest Obsessed | D32: =Matrix!D25 -> Market Force Complaints Per 10k | G32: =Matrix!G25 -> 0.15 | I32: Week 1 | M32: =IF(J37<=Benchmarks!C5,Matrix!M25,IF(J37<Benchmarks!C6,Matrix!M26,IF(J37<Benchmarks!C7,Matrix!M27,Matrix!M28))) -> 0 | O32: =M32*$G$32 -> 0
I33: Week 2
I34: Week 3
I35: Week 4
I36: Week 5
I37: Total | J37: =IF(ISBLANK(K32),"",SUM(K31:K36)/(SUM(J31:J36)/10000))
J39: Slow Point | K39: PCC
D40: =Matrix!D30 -> Perfect Car Count | G40: =Matrix!G30 -> 0.1 | I40: Week 1 | K40: =IF(ISBLANK(J40),"",_xlfn.FLOOR.MATH(3600/(J40*(24*60)))) | M40: =IF(ISBLANK(J40),0,IF(J45>=Benchmarks!E4,Matrix!M30,IF(J45>=Benchmarks!E5,Matrix!M31,IF(J45>=Benchmarks!E6,Matrix!M32,Matrix!M33)))) -> 0 | O40: =M40*$G$40 -> 0 | S40: Tier 1 | T40: 0.024305556
I41: Week 2 | K41: =IF(ISBLANK(J41),"",_xlfn.FLOOR.MATH(3600/(J41*(24*60)))) | S41: Tier 2 | T41: 0.025694444
I42: Week 3 | K42: =IF(ISBLANK(J42),"",_xlfn.FLOOR.MATH(3600/(J42*(24*60)))) | S42: Tier 3 | T42: 0.026388889
I43: Week 4 | K43: =IF(ISBLANK(J43),"",_xlfn.FLOOR.MATH(3600/(J43*(24*60)))) | S43: Tier 4 | T43: 0.027083333
I44: Week 5 | K44: =IF(ISBLANK(J44),"",_xlfn.FLOOR.MATH(3600/(J44*(24*60))))
I45: Total | J45: =IF(ISBLANK(J40),"",3600/(AVERAGE(J40:J44)*(24*60)))
D47: =Matrix!D35 -> REV | G47: =Matrix!G35 -> Bonus or Penalty | I47: Grade | M47: =IF(J47=W47,Matrix!M35,IF(J47=W51,Matrix!M36,IF(J47=W52,Matrix!M37,0))) -> 0 | O47: =IF(M47=Matrix!M35,SUM(O13,O21,O28,O32,O40,O51,O59,O67)*0.25,IF(M47=Matrix!M36,Matrix!M36,IF(M47=Matrix!M37,Matrix!M37,0))) -> 0 | W47: A
W48: B
W49: C
J50: Budget | K50: T/Y | W50: D
B51: Sales | D51: =Matrix!D39 -> Sales Vs Budget with Bonus | G51: =Matrix!G39 -> 0.25 | I51: Week 1 | M51: =IF(J56="",0,IF(J56>=Benchmarks!K4,Matrix!M39,IF(J56>Benchmarks!K5,Matrix!M40,IF(J56=Benchmarks!K6,Matrix!M41,Matrix!M42)))) -> 0 | O51: =M51*$G$51 -> 0 | S51: =J51/T6 -> 0 | T51: =K51 -> 0 | U51: =(T51-S51)/S51 -> #DIV/0! | W51: 1st Fail
I52: Week 2 | S52: =S51*2 -> 0 | T52: =SUM(K51:K52) -> 0 | U52: =(T52-S52)/S52 -> #DIV/0! | W52: 2nd Fail
...

Sheet Half 2
G3: RESTAURANT PERFORMANCE FACTOR FY2021-22
D6: Month: | G6: Half 2 | S6: Weeks | T6: 5
D8: Store:
D10: Metric | G10: Weights | I10: Weighted Points | M10: Points | O10: Total
B11: People
B12: Best People | D12: =Matrix!D10 -> Restaurant Proficiency | G12: =Matrix!G10 -> 0.1 | I12: Jan | J12: =IF(ISBLANK(INDIRECT(I12&"!J13")),"",INDIRECT(I12&"!O13")) | M12: =IF(J18<=0,100,IF(J18<5%,75,IF(J18<7.5%,50,IF(J18<10%,25,0)))) -> 100 | O12: =J18 -> 0
I13: Feb | J13: =IF(ISBLANK(INDIRECT(I13&"!J13")),"",INDIRECT(I13&"!O13"))
I14: Mar | J14: =IF(ISBLANK(INDIRECT(I14&"!J13")),"",INDIRECT(I14&"!O13"))
I15: Apr | J15: =IF(ISBLANK(INDIRECT(I15&"!J13")),"",INDIRECT(I15&"!O13"))
I16: May | J16: =IF(ISBLANK(INDIRECT(I16&"!J13")),"",INDIRECT(I16&"!O13"))
I17: Jun | J17: =IF(ISBLANK(INDIRECT(I17&"!J13")),"",INDIRECT(I17&"!O13"))
I18: Average | J18: =IFERROR(AVERAGE(J12:K17),0) -> 0
D20: =Matrix!D15 -> Crew Staffing Tiered by Sales Band | G20: =Matrix!G15 -> 0.1 | I20: Jan | J20: =IF(ISBLANK(INDIRECT(I12&"!K21")),"",INDIRECT(I12&"!O21")) | M20: =IFERROR(IF(ISBLANK(K20),0,IF(J26>=T26,100,IF(J26>=T23,75,IF(J26>=T22,50,IF(J26>=T21,25,0))))),0) -> 0 | O20: =J26 -> 0 | S20: Rounded Sales | T20: =FLOOR(U58,5000) -> #REF!
I21: Feb | J21: =IF(ISBLANK(INDIRECT(I13&"!K21")),"",INDIRECT(I13&"!O21")) | S21: Tier 1 | T21: =VLOOKUP($T$20,'Crew Staffing Bands'!$A$1:$E$23,2,FALSE) -> #REF!
I22: Mar | J22: =IF(ISBLANK(INDIRECT(I14&"!K21")),"",INDIRECT(I14&"!O21")) | S22: Tier 2 | T22: =VLOOKUP($T$20,'Crew Staffing Bands'!$A$1:$E$23,3,FALSE) -> #REF!
I23: Apr | J23: =IF(ISBLANK(INDIRECT(I15&"!K21")),"",INDIRECT(I15&"!O21")) | S23: Tier 3 | T23: =VLOOKUP($T$20,'Crew Staffing Bands'!$A$1:$E$23,4,FALSE) -> #REF!
I24: May | J24: =IF(ISBLANK(INDIRECT(I16&"!K21")),"",INDIRECT(I16&"!O21"))
I25: Jun | J25: =IF(ISBLANK(INDIRECT(I17&"!K21")),"",INDIRECT(I17&"!O21"))
I26: Average | J26: =IFERROR(AVERAGE(J20:K25),0) -> 0 | S26: Tier 4 | T26: =VLOOKUP($T$20,'Crew Staffing Bands'!$A$1:$E$23,5,FALSE) -> #REF!
D28: =Matrix!D20 -> Safety Audit (6 Monthly) | G28: =Matrix!G20 -> 0.05 | I28: H2 Result | J28: =IF(ISBLANK(Jun!J28),"Complete in June",Jun!J28) -> Complete in June | M28: =IF(J28="Complete in December",0,IF(J28>=0.95,100,IF(J28>=0.8,75,IF(J28>=0.7,50,IF(J28>=0.6,25,0))))) -> 100 | O28: =M28*$G$28 -> 5
B31: Guest Obsessed | D31: =Matrix!D25 -> Market Force Complaints Per 10k | G31: =Matrix!G25 -> 0.15 | I31: Jan | J31: =IF(ISBLANK(INDIRECT(I12&"!K32")),"",INDIRECT(I12&"!O32")) | M31: =IF(J37<2.8,100,IF(J37<3.03,75,IF(J37<3.27,50,IF(J37<=3.5,25,0)))) -> 100 | O31: =J37 -> 0
I32: Feb | J32: =IF(ISBLANK(INDIRECT(I13&"!K32")),"",INDIRECT(I13&"!O32"))
I33: Mar | J33: =IF(ISBLANK(INDIRECT(I14&"!K32")),"",INDIRECT(I14&"!O32"))
I34: Apr | J34: =IF(ISBLANK(INDIRECT(I15&"!K32")),"",INDIRECT(I15&"!O32"))
I35: May | J35: =IF(ISBLANK(INDIRECT(I16&"!K32")),"",INDIRECT(I16&"!O32"))
I36: Jun | J36: =IF(ISBLANK(INDIRECT(I17&"!K32")),"",INDIRECT(I17&"!O32"))
I37: Average | J37: =IFERROR(AVERAGE(J31:K36),0) -> 0
D39: =Matrix!D30 -> Perfect Car Count | G39: =Matrix!G30 -> 0.1 | I39: Jan | J39: =IF(ISBLANK(INDIRECT(I12&"!J40")),"",INDIRECT(I12&"!O40")) | M39: =IF(ISBLANK(J39),0,IF(J45<=T39,100,IF(J45<=T40,75,IF(J45<=T41,50,IF(J45<=T42,25,0))))) -> 100 | O39: =J45 -> 0 | S39: Tier 1 | T39: 0.024305556
I40: Feb | J40: =IF(ISBLANK(INDIRECT(I13&"!J40")),"",INDIRECT(I13&"!O40")) | S40: Tier 2 | T40: 0.025694444
I41: Mar | J41: =IF(ISBLANK(INDIRECT(I14&"!J40")),"",INDIRECT(I14&"!O40")) | S41: Tier 3 | T41: 0.026388889
I42: Apr | J42: =IF(ISBLANK(INDIRECT(I15&"!J40")),"",INDIRECT(I15&"!O40")) | S42: Tier 4 | T42: 0.027083333
I43: May | J43: =IF(ISBLANK(INDIRECT(I16&"!J40")),"",INDIRECT(I16&"!O40"))
I44: Jun | J44: =IF(ISBLANK(INDIRECT(I17&"!J40")),"",INDIRECT(I17&"!O40"))
I45: Average | J45: =IFERROR(AVERAGE(J39:K44),0) -> 0
D47: =Matrix!D35 -> REV | G47: =Matrix!G35 -> Bonus or Penalty | I47: Grade | J47: =IF(OR(Jul!J47="A",Aug!J47="A",Sep!J47="A",Oct!J47="A",Nov!J47="A",Dec!J47="A"),"A",IF(OR(Jul!J47="2nd Fail",Aug!J47="2nd Fail",Sep!J47="2nd Fail",Oct!J47="2nd Fail",Nov!J47="2nd Fail",Dec!J47="2nd Fail"),"2nd Fail",IF(OR(Jul!J47="1st Fail",Aug!J47="1st Fail",Dec!J47="1st Fail",Sep!J47="1st Fail",Oct!J47="1st Fail",Nov!J47="1st Fail"),"1st Fail","N/A"))) -> N/A | M47: =IF(J47=W47,Matrix!M35,IF(J47=W51,Matrix!M36,IF(J47=W52,Matrix!M37,0))) -> 0 | O47: =IF(M47=Matrix!M35,SUM(O12,O20,O28,O31,O39,O50,O58,O66)*0.25,IF(M47=Matrix!M36,Matrix!M36,IF(M47=Matrix!M37,Matrix!M37,0))) -> 0 | W47: A
W48: B
W49: C
B50: Sales | D50: =Matrix!D39 -> Sales Vs Budget with Bonus | G50: =Matrix!G39 -> 0.25 | I50: Jan | J50: =IF(ISBLANK(INDIRECT(I12&"!K51")),"",INDIRECT(I12&"!O51")) | M50: =IF(J56="",0,IF(J56>=3%,100,IF(J56>=2%,75,IF(J56>=1%,50,IF(J56>=0,25,0))))) -> 25 | O50: =J56 -> 0 | S50: =J50/T6 -> #VALUE! | T50: =K50 -> 0 | U50: =(T50-S50)/S50 -> #VALUE! | W50: 1st Fail
I51: Feb | J51: =IF(ISBLANK(INDIRECT(I13&"!K51")),"",INDIRECT(I13&"!O51")) | S51: =S50*2 -> #VALUE! | T51: =SUM(K50:K51) -> 0 | U51: =(T51-S51)/S51 -> #VALUE! | W51: 2nd Fail
I52: Mar | J52: =IF(ISBLANK(INDIRECT(I14&"!K51")),"",INDIRECT(I14&"!O51")) | S52: =S50*3 -> #VALUE! | T52: =SUM(K50:K52) -> 0 | U52: =(T52-S52)/S52 -> #VALUE!
...

Sheet Jan
D3: RESTAURANT PERFORMANCE FACTOR FY2022-23
D6: Month: | G6: January | S6: Weeks | T6: 4
D8: Store: | M8: State:
D10: Metric | G10: Weights | I10: Result | M10: Points | O10: Weighted Points
B11: People
J12: Proficiency %
B13: Best People | D13: =Matrix!D10 -> Restaurant Proficiency | G13: =Matrix!G10 -> 0.1 | I13: Week 1 | M13: =IF(J18="",0,IF(J18>=Benchmarks!G4,Matrix!M10,IF(J18>=Benchmarks!G5,Matrix!M11,IF(J18>=Benchmarks!G6,Matrix!M12,Matrix!M13)))) -> 0 | O13: =M13*$G$13 -> 0
I14: Week 2
I15: Week 3
I16: Week 4
I17: Week 5
I18: Total | J18: {=IF(ISBLANK(J13),"",(LOOKUP(2,1/(J13:J17<>""),J13:J17)))}
J20: Target | K20: Actual
D21: =Matrix!D15 -> Crew Staffing Tiered by Sales Band | G21: =Matrix!G15 -> 0.1 | I21: Week 1 | J21: =IFERROR(T26,"Enter Sales") -> Enter Sales | M21: =IFERROR(IF(ISBLANK(K21),0,IF(J26>=T26,Matrix!M15,IF(J26>=T24,Matrix!M16,IF(J26>=T23,Matrix!M17,Matrix!M18)))),0) -> 0 | O21: =M21*$G$21 -> 0 | S21: Rounded Sales | T21: =MROUND(U59,5000) -> 0
I22: Week 2 | S22: Tier 1 | T22: =VLOOKUP($T$21,'Crew Staffing Bands'!$A$1:$E$23,2,FALSE) -> #N/A
I23: Week 3 | S23: Tier 2 | T23: =VLOOKUP($T$21,'Crew Staffing Bands'!$A$1:$E$23,3,FALSE) -> #N/A
I24: Week 4 | S24: Tier 3 | T24: =VLOOKUP($T$21,'Crew Staffing Bands'!$A$1:$E$23,4,FALSE) -> #N/A
I25: Week 5
I26: Total | J26: {=IF(ISBLANK(K21),"",(LOOKUP(2,1/(K21:K25<>""),K21:K25)))} | S26: Tier 4 | T26: =VLOOKUP($T$21,'Crew Staffing Bands'!$A$1:$E$23,5,FALSE) -> #N/A
D28: =Matrix!D20 -> Safety Audit (6 Monthly) | G28: =Matrix!G20 -> 0.05 | I28: H1 Result | J28: =IF(ISBLANK(Jun!J28),"Complete in June",Jun!J28) -> Complete in June | M28: =IF(J28="Complete in December",0,IF(J28>=Benchmarks!I4,Matrix!M20,IF(J28>=Benchmarks!I5,Matrix!M21,IF(J28>=Benchmarks!I6,Matrix!M22,Matrix!M23)))) -> 100 | O28: =M28*$G$28 -> 5
J31: Customers | K31: Complaints
B32: Guest Obsessed | D32: =Matrix!D25 -> Market Force Complaints Per 10k | G32: =Matrix!G25 -> 0.15 | I32: Week 1 | M32: =IF(J37<=Benchmarks!C5,Matrix!M25,IF(J37<Benchmarks!C6,Matrix!M26,IF(J37<Benchmarks!C7,Matrix!M27,Matrix!M28))) -> 0 | O32: =M32*$G$32 -> 0
I33: Week 2
I34: Week 3
I35: Week 4
I36: Week 5
I37: Total | J37: =IF(ISBLANK(K32),"",SUM(K31:K36)/(SUM(J31:J36)/10000))
J39: Slow Point | K39: PCC
D40: =Matrix!D30 -> Perfect Car Count | G40: =Matrix!G30 -> 0.1 | I40: Week 1 | K40: =IF(ISBLANK(J40),"",_xlfn.FLOOR.MATH(3600/(J40*(24*60)))) | M40: =IF(ISBLANK(J40),0,IF(J45>=Benchmarks!E4,Matrix!M30,IF(J45>=Benchmarks!E5,Matrix!M31,IF(J45>=Benchmarks!E6,Matrix!M32,Matrix!M33)))) -> 0 | O40: =M40*$G$40 -> 0 | S40: Tier 1 | T40: 0.024305556
I41: Week 2 | K41: =IF(ISBLANK(J41),"",_xlfn.FLOOR.MATH(3600/(J41*(24*60)))) | S41: Tier 2 | T41: 0.025694444
I42: Week 3 | K42: =IF(ISBLANK(J42),"",_xlfn.FLOOR.MATH(3600/(J42*(24*60)))) | S42: Tier 3 | T42: 0.026388889
I43: Week 4 | K43: =IF(ISBLANK(J43),"",_xlfn.FLOOR.MATH(3600/(J43*(24*60)))) | S43: Tier 4 | T43: 0.027083333
I44: Week 5 | K44: =IF(ISBLANK(J44),"",_xlfn.FLOOR.MATH(3600/(J44*(24*60))))
I45: Total | J45: =IF(ISBLANK(J40),"",3600/(AVERAGE(J40:J44)*(24*60)))
D47: =Matrix!D35 -> REV | G47: =Matrix!G35 -> Bonus or Penalty | I47: Grade | M47: =IF(J47=W47,Matrix!M35,IF(J47=W51,Matrix!M36,IF(J47=W52,Matrix!M37,0))) -> 0 | O47: =IF(M47=Matrix!M35,SUM(O13,O21,O28,O32,O40,O51,O59,O67)*0.25,IF(M47=Matrix!M36,Matrix!M36,IF(M47=Matrix!M37,Matrix!M37,0))) -> 0 | W47: A
W48: B
W49: C
J50: Budget | K50: T/Y | W50: D
B51: Sales | D51: =Matrix!D39 -> Sales Vs Budget with Bonus | G51: =Matrix!G39 -> 0.25 | I51: Week 1 | M51: =IF(J56="",0,IF(J56>=Benchmarks!K4,Matrix!M39,IF(J56>Benchmarks!K5,Matrix!M40,IF(J56=Benchmarks!K6,Matrix!M41,Matrix!M42)))) -> 0 | O51: =M51*$G$51 -> 0 | S51: =J51/T6 -> 0 | T51: =K51 -> 0 | U51: =(T51-S51)/S51 -> #DIV/0! | W51: 1st Fail
I52: Week 2 | S52: =S51*2 -> 0 | T52: =SUM(K51:K52) -> 0 | U52: =(T52-S52)/S52 -> #DIV/0! | W52: 2nd Fail
...

Sheet Feb
D3: RESTAURANT PERFORMANCE FACTOR FY2022-23
D6: Month: | G6: February | S6: Weeks | T6: 4
D8: Store: | M8: State:
D10: Metric | G10: Weights | I10: Result | M10: Points | O10: Weighted Points
B11: People
J12: Proficiency %
B13: Best People | D13: =Matrix!D10 -> Restaurant Proficiency | G13: =Matrix!G10 -> 0.1 | I13: Week 1 | M13: =IF(J18="",0,IF(J18>=Benchmarks!G4,Matrix!M10,IF(J18>=Benchmarks!G5,Matrix!M11,IF(J18>=Benchmarks!G6,Matrix!M12,Matrix!M13)))) -> 0 | O13: =M13*$G$13 -> 0
I14: Week 2
I15: Week 3
I16: Week 4
I17: Week 5
I18: Total | J18: {=IF(ISBLANK(J13),"",(LOOKUP(2,1/(J13:J17<>""),J13:J17)))}
J20: Target | K20: Actual
D21: =Matrix!D15 -> Crew Staffing Tiered by Sales Band | G21: =Matrix!G15 -> 0.1 | I21: Week 1 | J21: =IFERROR(T26,"Enter Sales") -> Enter Sales | M21: =IFERROR(IF(ISBLANK(K21),0,IF(J26>=T26,Matrix!M15,IF(J26>=T24,Matrix!M16,IF(J26>=T23,Matrix!M17,Matrix!M18)))),0) -> 0 | O21: =M21*$G$21 -> 0 | S21: Rounded Sales | T21: =MROUND(U59,5000) -> 0
I22: Week 2 | S22: Tier 1 | T22: =VLOOKUP($T$21,'Crew Staffing Bands'!$A$1:$E$23,2,FALSE) -> #N/A
I23: Week 3 | S23: Tier 2 | T23: =VLOOKUP($T$21,'Crew Staffing Bands'!$A$1:$E$23,3,FALSE) -> #N/A
I24: Week 4 | S24: Tier 3 | T24: =VLOOKUP($T$21,'Crew Staffing Bands'!$A$1:$E$23,4,FALSE) -> #N/A
I25: Week 5
I26: Total | J26: {=IF(ISBLANK(K21),"",(LOOKUP(2,1/(K21:K25<>""),K21:K25)))} | S26: Tier 4 | T26: =VLOOKUP($T$21,'Crew Staffing Bands'!$A$1:$E$23,5,FALSE) -> #N/A
D28: =Matrix!D20 -> Safety Audit (6 Monthly) | G28: =Matrix!G20 -> 0.05 | I28: H1 Result | J28: =IF(ISBLANK(Jun!J28),"Complete in June",Jun!J28) -> Complete in June | M28: =IF(J28="Complete in December",0,IF(J28>=Benchmarks!I4,Matrix!M20,IF(J28>=Benchmarks!I5,Matrix!M21,IF(J28>=Benchmarks!I6,Matrix!M22,Matrix!M23)))) -> 100 | O28: =M28*$G$28 -> 5
J31: Customers | K31: Complaints
B32: Guest Obsessed | D32: =Matrix!D25 -> Market Force Complaints Per 10k | G32: =Matrix!G25 -> 0.15 | I32: Week 1 | M32: =IF(J37<=Benchmarks!C5,Matrix!M25,IF(J37<Benchmarks!C6,Matrix!M26,IF(J37<Benchmarks!C7,Matrix!M27,Matrix!M28))) -> 0 | O32: =M32*$G$32 -> 0
I33: Week 2
I34: Week 3
I35: Week 4
I36: Week 5
I37: Total | J37: =IF(ISBLANK(K32),"",SUM(K31:K36)/(SUM(J31:J36)/10000))
J39: Slow Point | K39: PCC
D40: =Matrix!D30 -> Perfect Car Count | G40: =Matrix!G30 -> 0.1 | I40: Week 1 | K40: =IF(ISBLANK(J40),"",_xlfn.FLOOR.MATH(3600/(J40*(24*60)))) | M40: =IF(ISBLANK(J40),0,IF(J45>=Benchmarks!E4,Matrix!M30,IF(J45>=Benchmarks!E5,Matrix!M31,IF(J45>=Benchmarks!E6,Matrix!M32,Matrix!M33)))) -> 0 | O40: =M40*$G$40 -> 0 | S40: Tier 1 | T40: 0.024305556
I41: Week 2 | K41: =IF(ISBLANK(J41),"",_xlfn.FLOOR.MATH(3600/(J41*(24*60)))) | S41: Tier 2 | T41: 0.025694444
I42: Week 3 | K42: =IF(ISBLANK(J42),"",_xlfn.FLOOR.MATH(3600/(J42*(24*60)))) | S42: Tier 3 | T42: 0.026388889
I43: Week 4 | K43: =IF(ISBLANK(J43),"",_xlfn.FLOOR.MATH(3600/(J43*(24*60)))) | S43: Tier 4 | T43: 0.027083333
I44: Week 5 | K44: =IF(ISBLANK(J44),"",_xlfn.FLOOR.MATH(3600/(J44*(24*60))))
I45: Total | J45: =IF(ISBLANK(J40),"",3600/(AVERAGE(J40:J44)*(24*60)))
D47: =Matrix!D35 -> REV | G47: =Matrix!G35 -> Bonus or Penalty | I47: Grade | M47: =IF(J47=W47,Matrix!M35,IF(J47=W51,Matrix!M36,IF(J47=W52,Matrix!M37,0))) -> 0 | O47: =IF(M47=Matrix!M35,SUM(O13,O21,O28,O32,O40,O51,O59,O67)*0.25,IF(M47=Matrix!M36,Matrix!M36,IF(M47=Matrix!M37,Matrix!M37,0))) -> 0 | W47: A
W48: B
W49: C
J50: Budget | K50: T/Y | W50: D
B51: Sales | D51: =Matrix!D39 -> Sales Vs Budget with Bonus | G51: =Matrix!G39 -> 0.25 | I51: Week 1 | M51: =IF(J56="",0,IF(J56>=Benchmarks!K4,Matrix!M39,IF(J56>Benchmarks!K5,Matrix!M40,IF(J56=Benchmarks!K6,Matrix!M41,Matrix!M42)))) -> 0 | O51: =M51*$G$51 -> 0 | S51: =J51/T6 -> 0 | T51: =K51 -> 0 | U51: =(T51-S51)/S51 -> #DIV/0! | W51: 1st Fail
I52: Week 2 | S52: =S51*2 -> 0 | T52: =SUM(K51:K52) -> 0 | U52: =(T52-S52)/S52 -> #DIV/0! | W52: 2nd Fail
...

Sheet Mar
D3: RESTAURANT PERFORMANCE FACTOR FY2022-23
D6: Month: | G6: March | S6: Weeks | T6: 5
D8: Store: | M8: State:
D10: Metric | G10: Weights | I10: Result | M10: Points | O10: Weighted Points
B11: People
J12: Proficiency %
B13: Best People | D13: =Matrix!D10 -> Restaurant Proficiency | G13: =Matrix!G10 -> 0.1 | I13: Week 1 | M13: =IF(J18="",0,IF(J18>=Benchmarks!G4,Matrix!M10,IF(J18>=Benchmarks!G5,Matrix!M11,IF(J18>=Benchmarks!G6,Matrix!M12,Matrix!M13)))) -> 0 | O13: =M13*$G$13 -> 0
I14: Week 2
I15: Week 3
I16: Week 4
I17: Week 5
I18: Total | J18: {=IF(ISBLANK(J13),"",(LOOKUP(2,1/(J13:J17<>""),J13:J17)))}
J20: Target | K20: Actual
D21: =Matrix!D15 -> Crew Staffing Tiered by Sales Band | G21: =Matrix!G15 -> 0.1 | I21: Week 1 | J21: =IFERROR(T26,"Enter Sales") -> Enter Sales | M21: =IFERROR(IF(ISBLANK(K21),0,IF(J26>=T26,Matrix!M15,IF(J26>=T24,Matrix!M16,IF(J26>=T23,Matrix!M17,Matrix!M18)))),0) -> 0 | O21: =M21*$G$21 -> 0 | S21: Rounded Sales | T21: =MROUND(U59,5000) -> 0
I22: Week 2 | S22: Tier 1 | T22: =VLOOKUP($T$21,'Crew Staffing Bands'!$A$1:$E$23,2,FALSE) -> #N/A
I23: Week 3 | S23: Tier 2 | T23: =VLOOKUP($T$21,'Crew Staffing Bands'!$A$1:$E$23,3,FALSE) -> #N/A
I24: Week 4 | S24: Tier 3 | T24: =VLOOKUP($T$21,'Crew Staffing Bands'!$A$1:$E$23,4,FALSE) -> #N/A
I25: Week 5
I26: Total | J26: {=IF(ISBLANK(K21),"",(LOOKUP(2,1/(K21:K25<>""),K21:K25)))} | S26: Tier 4 | T26: =VLOOKUP($T$21,'Crew Staffing Bands'!$A$1:$E$23,5,FALSE) -> #N/A
D28: =Matrix!D20 -> Safety Audit (6 Monthly) | G28: =Matrix!G20 -> 0.05 | I28: H1 Result | J28: =IF(ISBLANK(Jun!J28),"Complete in June",Jun!J28) -> Complete in June | M28: =IF(J28="Complete in December",0,IF(J28>=Benchmarks!I4,Matrix!M20,IF(J28>=Benchmarks!I5,Matrix!M21,IF(J28>=Benchmarks!I6,Matrix!M22,Matrix!M23)))) -> 100 | O28: =M28*$G$28 -> 5
J31: Customers | K31: Complaints
B32: Guest Obsessed | D32: =Matrix!D25 -> Market Force Complaints Per 10k | G32: =Matrix!G25 -> 0.15 | I32: Week 1 | M32: =IF(J37<=Benchmarks!C5,Matrix!M25,IF(J37<Benchmarks!C6,Matrix!M26,IF(J37<Benchmarks!C7,Matrix!M27,Matrix!M28))) -> 0 | O32: =M32*$G$32 -> 0
I33: Week 2
I34: Week 3
I35: Week 4
I36: Week 5
I37: Total | J37: =IF(ISBLANK(K32),"",SUM(K31:K36)/(SUM(J31:J36)/10000))
J39: Slow Point | K39: PCC
D40: =Matrix!D30 -> Perfect Car Count | G40: =Matrix!G30 -> 0.1 | I40: Week 1 | K40: =IF(ISBLANK(J40),"",_xlfn.FLOOR.MATH(3600/(J40*(24*60)))) | M40: =IF(ISBLANK(J40),0,IF(J45>=Benchmarks!E4,Matrix!M30,IF(J45>=Benchmarks!E5,Matrix!M31,IF(J45>=Benchmarks!E6,Matrix!M32,Matrix!M33)))) -> 0 | O40: =M40*$G$40 -> 0 | S40: Tier 1 | T40: 0.024305556
I41: Week 2 | K41: =IF(ISBLANK(J41),"",_xlfn.FLOOR.MATH(3600/(J41*(24*60)))) | S41: Tier 2 | T41: 0.025694444
I42: Week 3 | K42: =IF(ISBLANK(J42),"",_xlfn.FLOOR.MATH(3600/(J42*(24*60)))) | S42: Tier 3 | T42: 0.026388889
I43: Week 4 | K43: =IF(ISBLANK(J43),"",_xlfn.FLOOR.MATH(3600/(J43*(24*60)))) | S43: Tier 4 | T43: 0.027083333
I44: Week 5 | K44: =IF(ISBLANK(J44),"",_xlfn.FLOOR.MATH(3600/(J44*(24*60))))
I45: Total | J45: =IF(ISBLANK(J40),"",3600/(AVERAGE(J40:J44)*(24*60)))
D47: =Matrix!D35 -> REV | G47: =Matrix!G35 -> Bonus or Penalty | I47: Grade | M47: =IF(J47=W47,Matrix!M35,IF(J47=W51,Matrix!M36,IF(J47=W52,Matrix!M37,0))) -> 0 | O47: =IF(M47=Matrix!M35,SUM(O13,O21,O28,O32,O40,O51,O59,O67)*0.25,IF(M47=Matrix!M36,Matrix!M36,IF(M47=Matrix!M37,Matrix!M37,0))) -> 0 | W47: A
W48: B
W49: C
J50: Budget | K50: T/Y | W50: D
B51: Sales | D51: =Matrix!D39 -> Sales Vs Budget with Bonus | G51: =Matrix!G39 -> 0.25 | I51: Week 1 | M51: =IF(J56="",0,IF(J56>=Benchmarks!K4,Matrix!M39,IF(J56>Benchmarks!K5,Matrix!M40,IF(J56=Benchmarks!K6,Matrix!M41,Matrix!M42)))) -> 0 | O51: =M51*$G$51 -> 0 | S51: =J51/T6 -> 0 | T51: =K51 -> 0 | U51: =(T51-S51)/S51 -> #DIV/0! | W51: 1st Fail
I52: Week 2 | S52: =S51*2 -> 0 | T52: =SUM(K51:K52) -> 0 | U52: =(T52-S52)/S52 -> #DIV/0! | W52: 2nd Fail
...

Sheet Apr
D3: RESTAURANT PERFORMANCE FACTOR FY2022-23
D6: Month: | G6: April | S6: Weeks | T6: 4
D8: Store: | M8: State:
D10: Metric | G10: Weights | I10: Result | M10: Points | O10: Weighted Points
B11: People
J12: Proficiency %
B13: Best People | D13: =Matrix!D10 -> Restaurant Proficiency | G13: =Matrix!G10 -> 0.1 | I13: Week 1 | M13: =IF(J18="",0,IF(J18>=Benchmarks!G4,Matrix!M10,IF(J18>=Benchmarks!G5,Matrix!M11,IF(J18>=Benchmarks!G6,Matrix!M12,Matrix!M13)))) -> 0 | O13: =M13*$G$13 -> 0
I14: Week 2
I15: Week 3
I16: Week 4
I17: Week 5
I18: Total | J18: {=IF(ISBLANK(J13),"",(LOOKUP(2,1/(J13:J17<>""),J13:J17)))}
J20: Target | K20: Actual
D21: =Matrix!D15 -> Crew Staffing Tiered by Sales Band | G21: =Matrix!G15 -> 0.1 | I21: Week 1 | J21: =IFERROR(T26,"Enter Sales") -> Enter Sales | M21: =IFERROR(IF(ISBLANK(K21),0,IF(J26>=T26,Matrix!M15,IF(J26>=T24,Matrix!M16,IF(J26>=T23,Matrix!M17,Matrix!M18)))),0) -> 0 | O21: =M21*$G$21 -> 0 | S21: Rounded Sales | T21: =MROUND(U59,5000) -> 0
I22: Week 2 | S22: Tier 1 | T22: =VLOOKUP($T$21,'Crew Staffing Bands'!$A$1:$E$23,2,FALSE) -> #N/A
I23: Week 3 | S23: Tier 2 | T23: =VLOOKUP($T$21,'Crew Staffing Bands'!$A$1:$E$23,3,FALSE) -> #N/A
I24: Week 4 | S24: Tier 3 | T24: =VLOOKUP($T$21,'Crew Staffing Bands'!$A$1:$E$23,4,FALSE) -> #N/A
I25: Week 5
I26: Total | J26: {=IF(ISBLANK(K21),"",(LOOKUP(2,1/(K21:K25<>""),K21:K25)))} | S26: Tier 4 | T26: =VLOOKUP($T$21,'Crew Staffing Bands'!$A$1:$E$23,5,FALSE) -> #N/A
D28: =Matrix!D20 -> Safety Audit (6 Monthly) | G28: =Matrix!G20 -> 0.05 | I28: H1 Result | J28: =IF(ISBLANK(Jun!J28),"Complete in June",Jun!J28) -> Complete in June | M28: =IF(J28="Complete in December",0,IF(J28>=Benchmarks!I4,Matrix!M20,IF(J28>=Benchmarks!I5,Matrix!M21,IF(J28>=Benchmarks!I6,Matrix!M22,Matrix!M23)))) -> 100 | O28: =M28*$G$28 -> 5
J31: Customers | K31: Complaints
B32: Guest Obsessed | D32: =Matrix!D25 -> Market Force Complaints Per 10k | G32: =Matrix!G25 -> 0.15 | I32: Week 1 | M32: =IF(J37<=Benchmarks!C5,Matrix!M25,IF(J37<Benchmarks!C6,Matrix!M26,IF(J37<Benchmarks!C7,Matrix!M27,Matrix!M28))) -> 0 | O32: =M32*$G$32 -> 0
I33: Week 2
I34: Week 3
I35: Week 4
I36: Week 5
I37: Total | J37: =IF(ISBLANK(K32),"",SUM(K31:K36)/(SUM(J31:J36)/10000))
J39: Slow Point | K39: PCC
D40: =Matrix!D30 -> Perfect Car Count | G40: =Matrix!G30 -> 0.1 | I40: Week 1 | K40: =IF(ISBLANK(J40),"",_xlfn.FLOOR.MATH(3600/(J40*(24*60)))) | M40: =IF(ISBLANK(J40),0,IF(J45>=Benchmarks!E4,Matrix!M30,IF(J45>=Benchmarks!E5,Matrix!M31,IF(J45>=Benchmarks!E6,Matrix!M32,Matrix!M33)))) -> 0 | O40: =M40*$G$40 -> 0 | S40: Tier 1 | T40: 0.024305556
I41: Week 2 | K41: =IF(ISBLANK(J41),"",_xlfn.FLOOR.MATH(3600/(J41*(24*60)))) | S41: Tier 2 | T41: 0.025694444
I42: Week 3 | K42: =IF(ISBLANK(J42),"",_xlfn.FLOOR.MATH(3600/(J42*(24*60)))) | S42: Tier 3 | T42: 0.026388889
I43: Week 4 | K43: =IF(ISBLANK(J43),"",_xlfn.FLOOR.MATH(3600/(J43*(24*60)))) | S43: Tier 4 | T43: 0.027083333
I44: Week 5 | K44: =IF(ISBLANK(J44),"",_xlfn.FLOOR.MATH(3600/(J44*(24*60))))
I45: Total | J45: =IF(ISBLANK(J40),"",3600/(AVERAGE(J40:J44)*(24*60)))
D47: =Matrix!D35 -> REV | G47: =Matrix!G35 -> Bonus or Penalty | I47: Grade | M47: =IF(J47=W47,Matrix!M35,IF(J47=W51,Matrix!M36,IF(J47=W52,Matrix!M37,0))) -> 0 | O47: =IF(M47=Matrix!M35,SUM(O13,O21,O28,O32,O40,O51,O59,O67)*0.25,IF(M47=Matrix!M36,Matrix!M36,IF(M47=Matrix!M37,Matrix!M37,0))) -> 0 | W47: A
W48: B
W49: C
J50: Budget | K50: T/Y | W50: D
B51: Sales | D51: =Matrix!D39 -> Sales Vs Budget with Bonus | G51: =Matrix!G39 -> 0.25 | I51: Week 1 | M51: =IF(J56="",0,IF(J56>=Benchmarks!K4,Matrix!M39,IF(J56>Benchmarks!K5,Matrix!M40,IF(J56=Benchmarks!K6,Matrix!M41,Matrix!M42)))) -> 0 | O51: =M51*$G$51 -> 0 | S51: =J51/T6 -> 0 | T51: =K51 -> 0 | U51: =(T51-S51)/S51 -> #DIV/0! | W51: 1st Fail
I52: Week 2 | S52: =S51*2 -> 0 | T52: =SUM(K51:K52) -> 0 | U52: =(T52-S52)/S52 -> #DIV/0! | W52: 2nd Fail
...

Sheet May
D3: RESTAURANT PERFORMANCE FACTOR FY2022-23
D6: Month: | G6: May | S6: Weeks | T6: 4
D8: Store: | M8: State:
D10: Metric | G10: Weights | I10: Result | M10: Points | O10: Weighted Points
B11: People
J12: Proficiency %
B13: Best People | D13: =Matrix!D10 -> Restaurant Proficiency | G13: =Matrix!G10 -> 0.1 | I13: Week 1 | M13: =IF(J18="",0,IF(J18>=Benchmarks!G4,Matrix!M10,IF(J18>=Benchmarks!G5,Matrix!M11,IF(J18>=Benchmarks!G6,Matrix!M12,Matrix!M13)))) -> 0 | O13: =M13*$G$13 -> 0
I14: Week 2
I15: Week 3
I16: Week 4
I17: Week 5
I18: Total | J18: {=IF(ISBLANK(J13),"",(LOOKUP(2,1/(J13:J17<>""),J13:J17)))}
J20: Target | K20: Actual
D21: =Matrix!D15 -> Crew Staffing Tiered by Sales Band | G21: =Matrix!G15 -> 0.1 | I21: Week 1 | J21: =IFERROR(T26,"Enter Sales") -> Enter Sales | M21: =IFERROR(IF(ISBLANK(K21),0,IF(J26>=T26,Matrix!M15,IF(J26>=T24,Matrix!M16,IF(J26>=T23,Matrix!M17,Matrix!M18)))),0) -> 0 | O21: =M21*$G$21 -> 0 | S21: Rounded Sales | T21: =MROUND(U59,5000) -> 0
I22: Week 2 | S22: Tier 1 | T22: =VLOOKUP($T$21,'Crew Staffing Bands'!$A$1:$E$23,2,FALSE) -> #N/A
I23: Week 3 | S23: Tier 2 | T23: =VLOOKUP($T$21,'Crew Staffing Bands'!$A$1:$E$23,3,FALSE) -> #N/A
I24: Week 4 | S24: Tier 3 | T24: =VLOOKUP($T$21,'Crew Staffing Bands'!$A$1:$E$23,4,FALSE) -> #N/A
I25: Week 5
I26: Total | J26: {=IF(ISBLANK(K21),"",(LOOKUP(2,1/(K21:K25<>""),K21:K25)))} | S26: Tier 4 | T26: =VLOOKUP($T$21,'Crew Staffing Bands'!$A$1:$E$23,5,FALSE) -> #N/A
D28: =Matrix!D20 -> Safety Audit (6 Monthly) | G28: =Matrix!G20 -> 0.05 | I28: H1 Result | J28: =IF(ISBLANK(Jun!J28),"Complete in June",Jun!J28) -> Complete in June | M28: =IF(J28="Complete in December",0,IF(J28>=Benchmarks!I4,Matrix!M20,IF(J28>=Benchmarks!I5,Matrix!M21,IF(J28>=Benchmarks!I6,Matrix!M22,Matrix!M23)))) -> 100 | O28: =M28*$G$28 -> 5
J31: Customers | K31: Complaints
B32: Guest Obsessed | D32: =Matrix!D25 -> Market Force Complaints Per 10k | G32: =Matrix!G25 -> 0.15 | I32: Week 1 | M32: =IF(J37<=Benchmarks!C5,Matrix!M25,IF(J37<Benchmarks!C6,Matrix!M26,IF(J37<Benchmarks!C7,Matrix!M27,Matrix!M28))) -> 0 | O32: =M32*$G$32 -> 0
I33: Week 2
I34: Week 3
I35: Week 4
I36: Week 5
I37: Total | J37: =IF(ISBLANK(K32),"",SUM(K31:K36)/(SUM(J31:J36)/10000))
J39: Slow Point | K39: PCC
D40: =Matrix!D30 -> Perfect Car Count | G40: =Matrix!G30 -> 0.1 | I40: Week 1 | K40: =IF(ISBLANK(J40),"",_xlfn.FLOOR.MATH(3600/(J40*(24*60)))) | M40: =IF(ISBLANK(J40),0,IF(J45>=Benchmarks!E4,Matrix!M30,IF(J45>=Benchmarks!E5,Matrix!M31,IF(J45>=Benchmarks!E6,Matrix!M32,Matrix!M33)))) -> 0 | O40: =M40*$G$40 -> 0 | S40: Tier 1 | T40: 0.024305556
I41: Week 2 | K41: =IF(ISBLANK(J41),"",_xlfn.FLOOR.MATH(3600/(J41*(24*60)))) | S41: Tier 2 | T41: 0.025694444
I42: Week 3 | K42: =IF(ISBLANK(J42),"",_xlfn.FLOOR.MATH(3600/(J42*(24*60)))) | S42: Tier 3 | T42: 0.026388889
I43: Week 4 | K43: =IF(ISBLANK(J43),"",_xlfn.FLOOR.MATH(3600/(J43*(24*60)))) | S43: Tier 4 | T43: 0.027083333
I44: Week 5 | K44: =IF(ISBLANK(J44),"",_xlfn.FLOOR.MATH(3600/(J44*(24*60))))
I45: Total | J45: =IF(ISBLANK(J40),"",3600/(AVERAGE(J40:J44)*(24*60)))
D47: =Matrix!D35 -> REV | G47: =Matrix!G35 -> Bonus or Penalty | I47: Grade | M47: =IF(J47=W47,Matrix!M35,IF(J47=W51,Matrix!M36,IF(J47=W52,Matrix!M37,0))) -> 0 | O47: =IF(M47=Matrix!M35,SUM(O13,O21,O28,O32,O40,O51,O59,O67)*0.25,IF(M47=Matrix!M36,Matrix!M36,IF(M47=Matrix!M37,Matrix!M37,0))) -> 0 | W47: A
W48: B
W49: C
J50: Budget | K50: T/Y | W50: D
B51: Sales | D51: =Matrix!D39 -> Sales Vs Budget with Bonus | G51: =Matrix!G39 -> 0.25 | I51: Week 1 | M51: =IF(J56="",0,IF(J56>=Benchmarks!K4,Matrix!M39,IF(J56>Benchmarks!K5,Matrix!M40,IF(J56=Benchmarks!K6,Matrix!M41,Matrix!M42)))) -> 0 | O51: =M51*$G$51 -> 0 | S51: =J51/T6 -> 0 | T51: =K51 -> 0 | U51: =(T51-S51)/S51 -> #DIV/0! | W51: 1st Fail
I52: Week 2 | S52: =S51*2 -> 0 | T52: =SUM(K51:K52) -> 0 | U52: =(T52-S52)/S52 -> #DIV/0! | W52: 2nd Fail
...

Sheet Jun
D3: RESTAURANT PERFORMANCE FACTOR FY2022-23
D6: Month: | G6: June | S6: Weeks | T6: 5
D8: Store: | M8: State:
D10: Metric | G10: Weights | I10: Result | M10: Points | O10: Weighted Points
B11: People
J12: Proficiency %
B13: Best People | D13: =Matrix!D10 -> Restaurant Proficiency | G13: =Matrix!G10 -> 0.1 | I13: Week 1 | M13: =IF(J18="",0,IF(J18>=Benchmarks!G4,Matrix!M10,IF(J18>=Benchmarks!G5,Matrix!M11,IF(J18>=Benchmarks!G6,Matrix!M12,Matrix!M13)))) -> 0 | O13: =M13*$G$13 -> 0
I14: Week 2
I15: Week 3
I16: Week 4
I17: Week 5
I18: Total | J18: {=IF(ISBLANK(J13),"",(LOOKUP(2,1/(J13:J17<>""),J13:J17)))}
J20: Target | K20: Actual
D21: =Matrix!D15 -> Crew Staffing Tiered by Sales Band | G21: =Matrix!G15 -> 0.1 | I21: Week 1 | J21: =IFERROR(T26,"Enter Sales") -> Enter Sales | M21: =IFERROR(IF(ISBLANK(K21),0,IF(J26>=T26,Matrix!M15,IF(J26>=T24,Matrix!M16,IF(J26>=T23,Matrix!M17,Matrix!M18)))),0) -> 0 | O21: =M21*$G$21 -> 0 | S21: Rounded Sales | T21: =MROUND(U59,5000) -> 0
I22: Week 2 | S22: Tier 1 | T22: =VLOOKUP($T$21,'Crew Staffing Bands'!$A$1:$E$23,2,FALSE) -> #N/A
I23: Week 3 | S23: Tier 2 | T23: =VLOOKUP($T$21,'Crew Staffing Bands'!$A$1:$E$23,3,FALSE) -> #N/A
I24: Week 4 | S24: Tier 3 | T24: =VLOOKUP($T$21,'Crew Staffing Bands'!$A$1:$E$23,4,FALSE) -> #N/A
I25: Week 5
I26: Total | J26: {=IF(ISBLANK(K21),"",(LOOKUP(2,1/(K21:K25<>""),K21:K25)))} | S26: Tier 4 | T26: =VLOOKUP($T$21,'Crew Staffing Bands'!$A$1:$E$23,5,FALSE) -> #N/A
D28: =Matrix!D20 -> Safety Audit (6 Monthly) | G28: =Matrix!G20 -> 0.05 | I28: H1 Result | M28: =IF(J28="Complete in December",0,IF(J28>=Benchmarks!I4,Matrix!M20,IF(J28>=Benchmarks!I5,Matrix!M21,IF(J28>=Benchmarks!I6,Matrix!M22,Matrix!M23)))) -> 0 | O28: =M28*$G$28 -> 0
J31: Customers | K31: Complaints
B32: Guest Obsessed | D32: =Matrix!D25 -> Market Force Complaints Per 10k | G32: =Matrix!G25 -> 0.15 | I32: Week 1 | M32: =IF(J37<=Benchmarks!C5,Matrix!M25,IF(J37<Benchmarks!C6,Matrix!M26,IF(J37<Benchmarks!C7,Matrix!M27,Matrix!M28))) -> 0 | O32: =M32*$G$32 -> 0
I33: Week 2
I34: Week 3
I35: Week 4
I36: Week 5
I37: Total | J37: =IF(ISBLANK(K32),"",SUM(K31:K36)/(SUM(J31:J36)/10000))
J39: Slow Point | K39: PCC
D40: =Matrix!D30 -> Perfect Car Count | G40: =Matrix!G30 -> 0.1 | I40: Week 1 | K40: =IF(ISBLANK(J40),"",_xlfn.FLOOR.MATH(3600/(J40*(24*60)))) | M40: =IF(ISBLANK(J40),0,IF(J45>=Benchmarks!E4,Matrix!M30,IF(J45>=Benchmarks!E5,Matrix!M31,IF(J45>=Benchmarks!E6,Matrix!M32,Matrix!M33)))) -> 0 | O40: =M40*$G$40 -> 0 | S40: Tier 1 | T40: 0.024305556
I41: Week 2 | K41: =IF(ISBLANK(J41),"",_xlfn.FLOOR.MATH(3600/(J41*(24*60)))) | S41: Tier 2 | T41: 0.025694444
I42: Week 3 | K42: =IF(ISBLANK(J42),"",_xlfn.FLOOR.MATH(3600/(J42*(24*60)))) | S42: Tier 3 | T42: 0.026388889
I43: Week 4 | K43: =IF(ISBLANK(J43),"",_xlfn.FLOOR.MATH(3600/(J43*(24*60)))) | S43: Tier 4 | T43: 0.027083333
I44: Week 5 | K44: =IF(ISBLANK(J44),"",_xlfn.FLOOR.MATH(3600/(J44*(24*60))))
I45: Total | J45: =IF(ISBLANK(J40),"",3600/(AVERAGE(J40:J44)*(24*60)))
D47: =Matrix!D35 -> REV | G47: =Matrix!G35 -> Bonus or Penalty | I47: Grade | M47: =IF(J47=W47,Matrix!M35,IF(J47=W51,Matrix!M36,IF(J47=W52,Matrix!M37,0))) -> 0 | O47: =IF(M47=Matrix!M35,SUM(O13,O21,O28,O32,O40,O51,O59,O67)*0.25,IF(M47=Matrix!M36,Matrix!M36,IF(M47=Matrix!M37,Matrix!M37,0))) -> 0 | W47: A
W48: B
W49: C
J50: Budget | K50: T/Y | W50: D
B51: Sales | D51: =Matrix!D39 -> Sales Vs Budget with Bonus | G51: =Matrix!G39 -> 0.25 | I51: Week 1 | M51: =IF(J56="",0,IF(J56>=Benchmarks!K4,Matrix!M39,IF(J56>Benchmarks!K5,Matrix!M40,IF(J56=Benchmarks!K6,Matrix!M41,Matrix!M42)))) -> 0 | O51: =M51*$G$51 -> 0 | S51: =J51/T6 -> 0 | T51: =K51 -> 0 | U51: =(T51-S51)/S51 -> #DIV/0! | W51: 1st Fail
I52: Week 2 | S52: =S51*2 -> 0 | T52: =SUM(K51:K52) -> 0 | U52: =(T52-S52)/S52 -> #DIV/0! | W52: 2nd Fail
...

Sheet Crew Staffing Bands
A1: Average Sales | B1: 25 Points | C1: 50 Points | D1: 75 Points | E1: 100 Points
A2: 10000 | B2: 15 | C2: 16 | D2: 17 | E2: 18
A3: 15000 | B3: 15 | C3: 16 | D3: 17 | E3: 18
A4: 20000 | B4: 15 | C4: 16 | D4: 17 | E4: 18
A5: 25000 | B5: 20 | C5: 21 | D5: 22 | E5: 23
A6: 30000 | B6: 24 | C6: 25 | D6: 26 | E6: 27
A7: 35000 | B7: 28 | C7: 29 | D7: 30 | E7: 32
A8: 40000 | B8: 32 | C8: 33 | D8: 34 | E8: 36
A9: 45000 | B9: 36 | C9: 37 | D9: 39 | E9: 41
A10: 50000 | B10: 40 | C10: 41 | D10: 43 | E10: 45
A11: 55000 | B11: 43 | C11: 44 | D11: 46 | E11: 48
A12: 60000 | B12: 46 | C12: 47 | D12: 49 | E12: 51
A13: 65000 | B13: 48 | C13: 50 | D13: 52 | E13: 55
... A23: 115000 | B23: 68 | C23: 70 | D23: 73 | E23: 77

Sheet AHR Benchmarks
